<?xml version="1.0" ?>
<robot name="indy7" xmlns:xacro="http://www.ros.org/wiki/xacro">
  <material name="black">
    <color rgba="0.0 0.0 0.0 1.0"/>
  </material>
  <material name="blue">
    <color rgba="0.0 0.0 0.8 1.0"/>
  </material>
  <material name="green">
    <color rgba="0.0 0.8 0.0 1.0"/>
  </material>
  <material name="grey_">
    <color rgba="0.2 0.2 0.2 1.0"/>
  </material>
  <material name="orange">
    <color rgba="1.0 0.423529411765 0.0392156862745 1.0"/>
  </material>
  <material name="brown">
    <color rgba="0.870588235294 0.811764705882 0.764705882353 1.0"/>
  </material>
  <material name="red">
    <color rgba="0.8 0.0 0.0 1.0"/>
  </material>
  <material name="white">
    <color rgba="1.0 1.0 1.0 1.0"/>
  </material>
  <material name="metal">
    <color rgba="0.768627450980392 0.749019607843137 0.729411764705882 1"/>
  </material>
  <material name="metal_grey">
    <color rgba="0.501960784313725 0.501960784313725 0.501960784313725 1"/>
  </material>
  <material name="metal_white">
    <color rgba="0.866666666666667 0.866666666666667 0.890196078431373 1"/>
  </material>

<link name="world">
  </link>
  <joint name="world_fixed" type="fixed">
    <origin rpy="0 0 0" xyz="0 0 0"/>
    <parent link="world"/>
    <child link="lbr_iiwa_link_0"/>
  </joint>

<link name="lbr_iiwa_link_0">
 <inertial>
      <origin rpy="0 0 0" xyz="0 0 0"/>
      <mass value="1.59306955" />
      <inertia ixx="+0.00572623" iyy="+0.00558959" izz="+0.00966674" ixy="+0.00000251" iyz="-0.00000014" ixz="-0.00011380"/>
    </inertial>
    <visual>
      <origin rpy="0 0 0" xyz="0 0 0"/>
      <geometry>
        <mesh filename="meshes/stl/Indy7_0.stl"/>
      </geometry>
      <material name="metal_grey"/>
    </visual>
    <collision>
      <origin rpy="0 0 0" xyz="0 0 0"/>
      <geometry>
        <mesh filename="meshes/stl/Indy7_0.stl"/>
      </geometry>
    </collision>
   


  </link>
  <joint name="lbr_iiwa_joint_1" type="continuous">
    <parent link="lbr_iiwa_link_0"/>
    <child link="lbr_iiwa_link_1"/>
    <origin xyz = "0 0 0.03000000" rpy = "0 0 0"/>
    <axis xyz = "0 0 1"/>
       <!--<limit effort="300" lower="-3.054325556" upper="3.054325556" velocity="10"/>
    <dynamics damping="0.5"/>-->
  </joint>

<link name="lbr_iiwa_link_1">
   <inertial>
      <origin rpy="0 0 0" xyz="0 0 0"/>
      <mass value="1.59306955" />
      <inertia ixx="+0.15418559" iyy="+0.12937017" izz="+0.05964415" ixy="-0.00000235" iyz="-0.04854267" ixz="+0.00001739" />
    </inertial>
    <visual>
      <origin rpy="0 0 0" xyz="0 0 0"/>
      <geometry>
        <mesh filename="meshes/stl/Indy7_1.stl"/>
      </geometry>
      <material name="metal_white"/>
    </visual>
    <collision>
      <origin rpy="0 0 0" xyz="0 0 0"/>
      <geometry>
        <mesh filename="meshes/stl/Indy7_1.stl"/>
      </geometry>
    </collision>
</link>
 <joint name="lbr_iiwa_joint_2" type="continuous">
    <parent link="lbr_iiwa_link_1"/>
    <child link="lbr_iiwa_link_2"/>
    <origin xyz = "0 -0.10900000 0.22200000" rpy = "1.570796 1.570796 0"/>
    	<axis xyz = "0 0 1"/>
   <!-- <limit effort="300" lower="-3.054325556" upper="3.054325556" velocity="10"/>
    <dynamics damping="0.5"/>-->
  </joint>
 <link name="lbr_iiwa_link_2">
 <inertial>
      <origin rpy="0 0 0" xyz="0 0 0"/>
      <mass value="0.18" />
      <inertia ixx="+0.29356980" iyy="+0.25088420" izz="+0.03620519" ixy="-0.00000040" iyz="+0.03727972" ixz="+0.00001441"/>
    </inertial>
    <visual>
      <origin rpy="0 0 0" xyz="0 0 0"/>
      <geometry>
        <mesh filename="meshes/stl/Indy7_2.stl"/>
      </geometry>
      <material name="metal_white"/>
    </visual>
    <collision>
      <origin rpy="0 0 0" xyz="0 0 0"/>
      <geometry>
        <mesh filename="meshes/stl/Indy7_2.stl"/>
      </geometry>
    </collision>
  </link>
  <joint name="lbr_iiwa_joint_3" type="continuous">
    <parent link="lbr_iiwa_link_2"/>
    <child link="lbr_iiwa_link_3"/>
    <origin xyz = "-0.45000000 +0.00000000 -0.03050000" rpy = "0 0 0"/>
    	<axis xyz = "0 0 1"/>
       <!--<limit effort="300" lower="-3.054325556" upper="3.054325556" velocity="10"/>
    <dynamics damping="0.5"/>-->
  </joint>
 <link name="lbr_iiwa_link_3">
   <inertial>
      <origin rpy="0 0 0" xyz="0 0 0"/>
      <mass value="0.18" />
      <inertia ixx="+0.03424593" iyy="+0.03406024" izz="+0.00450477" ixy="+0.00000149" iyz="+0.00186009" ixz="+0.00000724"/>
    </inertial>
    <visual>
      <origin rpy="0 0 0" xyz="0 0 0"/>
      <geometry>
        <mesh filename="meshes/stl/Indy7_3.stl"/>
      </geometry>
      <material name="metal_white"/>
    </visual>
    <collision>
      <origin rpy="0 0 0" xyz="0 0 0"/>
      <geometry>
        <mesh filename="meshes/stl/Indy7_3.stl"/>
      </geometry>
    </collision>collision
  </link>
  <joint name="lbr_iiwa_joint_4" type="continuous">
    <parent link="lbr_iiwa_link_3"/>
    <child link="lbr_iiwa_link_4"/>
    	<origin xyz = "-0.26700000 +0.00000000 -0.07500000" rpy = "-1.570796 0 1.570796"/>
    	<axis xyz = "0 0 1"/>
      <!-- <limit effort="300" lower="-3.054325556" upper="3.054325556" velocity="10"/>
    <dynamics damping="0.5"/>-->
  </joint>
  <link name="lbr_iiwa_link_4">
    <inertial>
      <origin rpy="0 0 0" xyz="0 0 0"/>
      <mass value="0.18" />
      <inertia ixx="+0.00670405" iyy="+0.00670405" izz="+0.00617624" ixy="+0.00000375" iyz="-0.00127967" ixz="+0.00000150"/>
    </inertial>
    <visual>
      <origin rpy="0 0 0" xyz="0 0 0"/>
      <geometry>
        <mesh filename="meshes/stl/Indy7_4.stl"/>
      </geometry>
      <material name="metal_white"/>
    </visual>
    <collision>
      <origin rpy="0 0 0" xyz="0 0 0"/>
      <geometry>
        <mesh filename="meshes/stl/Indy7_4.stl"/>
      </geometry>
    </collision>
  </link>
  <joint name="lbr_iiwa_joint_5" type="continuous">
    <parent link="lbr_iiwa_link_4"/>
    <child link="lbr_iiwa_link_5"/>
    <origin xyz = "+0.00000000 -0.11400000 +0.08300000" rpy = "1.570796 1.570796 0"/>
    <axis xyz = "0 0 1"/>
      <!-- <limit effort="300" lower="-3.054325556" upper="3.054325556" velocity="10"/>
    <dynamics damping="0.5"/>-->
  </joint>
  <link name="lbr_iiwa_link_5">
    <inertial>
      <origin rpy="0 0 0" xyz="0 0 0"/>
      <mass value="0.18" />
      <inertia ixx="+0.00994891" iyy="+0.00978189" izz="+0.00271492" ixy="+0.00000014" iyz="-0.00093546" ixz="+0.00000321"/>
    </inertial>
    <visual>
      <origin rpy="0 0 0" xyz="0 0 0"/>
      <geometry>
        <mesh filename="meshes/stl/Indy7_5.stl"/>
      </geometry>
      <material name="metal_white"/>
    </visual>
    <collision>
      <origin rpy="0 0 0" xyz="0 0 0"/>
      <geometry>
        <mesh filename="meshes/stl/Indy7_5.stl"/>
      </geometry>
    </collision>

  </link>
  <joint name="lbr_iiwa_joint_6" type="continuous">
    <parent link="lbr_iiwa_link_5"/>
    <child link="lbr_iiwa_link_6"/>
    <origin xyz = "-0.16800000 +0.00000000 +0.06900000" rpy = "-1.570796 0 1.570796"/>
    	<axis xyz = "0 0 1"/>
       <!--<limit effort="300" lower="-3.054325556" upper="3.054325556" velocity="10"/>
    <dynamics damping="0.5"/>-->
  </joint>
  <link name="lbr_iiwa_link_6">
    <inertial>
      <origin rpy="0 0 0" xyz="0 0 0"/>
      <mass value="0.18" />
      <inertia ixx="0.00043534" iyy="0.00044549" izz="0.00059634" ixy="+0.00000013" iyz="+0.00000051" ixz="-0.00000002"/>
    </inertial>
    <visual>
      <origin rpy="0 0 0" xyz="0 0 0"/>
      <geometry>
        <mesh filename="meshes/stl/Indy7_6.stl"/>
      </geometry>
      <material name="metal_white"/>
    </visual>
    <collision>
      <origin rpy="0 0 0" xyz="0 0 0"/>
      <geometry>
        <mesh filename="meshes/stl/Indy7_6.stl"/>
      </geometry>
    </collision>
  </link>
  <joint name="tcp_joint" type="fixed">
    <parent link="lbr_iiwa_link_6"/>
    <child link="tcp"/>
    <origin rpy="0 0 0" xyz="0.0 0 0.23"/>
    <axis xyz="0 0 1"/>
  </joint>
  <link name="tcp">
    <visual>
      <origin rpy="0 0 0" xyz="0 0 0"/>
      <geometry>
		<box size="0.01 0.01 0.01"/>	
      </geometry>
      <material name="orange"/>
    </visual>
  </link>

  <joint name="lbr_iiwa_joint_7" type="fixed">
    <parent link="lbr_iiwa_link_6"/>
    <child link="camera"/>
    <origin xyz = "-0.055 -0.033 0.1579" rpy = "0 0 0"/>
    	<axis xyz = "0 0 1"/>
       <!--<limit effort="300" lower="-3.054325556" upper="3.054325556" velocity="10"/>
    <dynamics damping="0.5"/>-->

  </joint>
  <link name="camera">
    <inertial>
      <origin rpy="0 0 0" xyz="0 0 0"/>
      <mass value="0.01" />
      <inertia ixx="0.00043534" iyy="0.00044549" izz="0.00059634" ixy="+0.00000013" iyz="+0.00000051" ixz="-0.00000002"/>
    </inertial>
    <visual>
      <origin rpy="0 0 0" xyz="0 0 0"/>
      <geometry>
        <mesh filename="meshes/stl/kinect-for-azure.stl"/>
      </geometry>
      <material name="white"/>
    </visual>
    <collision>
      <origin rpy="0 0 0" xyz="0 0 0"/>
      <geometry>
        <mesh filename="meshes/stl/kinect-for-azure.stl"/>
      </geometry>
      <material name="white"/>
    </collision>
  </link>

  <joint name="indy7_rh_p12_rn_fixed" type="fixed">
    <origin rpy="0 0 0" xyz="0 0 0.093"/>
    <parent link="lbr_iiwa_link_6"/>
    <child link="rh_p12_rn_base"/>
  </joint>

   <link name="rh_p12_rn_base">
    <collision>
      <origin rpy="0 0 0" xyz="0 0 0"/>
      <geometry>
        <mesh filename="meshes/stl/base.stl" scale="0.001 0.001 0.001"/>
      </geometry>
    </collision>
    <visual>
      <origin rpy="0 0 0" xyz="0 0 0"/>
      <geometry>
        <mesh filename="meshes/stl/base.stl" scale="0.001 0.001 0.001"/>
      </geometry>
      <material name="black"/>
    </visual>
    <inertial>
      <origin rpy="0 0 0" xyz="0.000 0.000 0.032"/>
      <mass value="0.236"/>
      <!--<inertia ixx="0.00017" ixy="0.0" ixz="0.0" iyy="0.00011" iyz="0.0" izz="0.00017" />-->
      <inertia ixx="1.0" ixy="0.0" ixz="0.0" iyy="1.0" iyz="0.0" izz="1.0"/>
    </inertial>
  </link>
 <joint name="rh_p12_rn" type="revolute">
    <parent link="rh_p12_rn_base"/>
    <child link="rh_p12_rn_r1"/>
    <origin rpy="0 0 0" xyz="0.0 0.008 0.048"/>
    <axis xyz="1 0 0"/>
    <limit effort="1000" lower="0.0" upper="1.1" velocity="6.5"/>
    <dynamics damping="0.7"/>
  </joint>
  
  <!-- rh_p12_rn_r1 -->
  <link name="rh_p12_rn_r1">
    <collision>
      <origin rpy="0 0 0" xyz="0 0 0"/>
      <geometry>
        <mesh filename="meshes/stl/r1.stl" scale="0.001 0.001 0.001"/>
      </geometry>
      <material name="black"/>
    </collision>
    <visual>
      <origin rpy="0 0 0" xyz="0 0 0"/>
      <geometry>
        <mesh filename="meshes/stl/r1.stl" scale="0.001 0.001 0.001"/>
      </geometry>
      <material name="black"/>
    </visual>
    <inertial>
      <origin rpy="0 0 0" xyz="0.000 0.034 0.004"/>
      <mass value="0.068"/>
      <!--<inertia ixx="0.00004" ixy="0.0" ixz="0.0" iyy="0.00002" iyz="-0.00001" izz="0.00002" />-->
      <inertia ixx="1.0" ixy="0.0" ixz="0.0" iyy="1.0" iyz="0.0" izz="1.0"/>
    </inertial>
  </link>
 <!-- Right Joint 2 -->
  <joint name="rh_r2" type="revolute">
    <parent link="rh_p12_rn_r1"/>
    <child link="rh_p12_rn_r2"/>
    <origin rpy="0 0 0" xyz="0.0 0.0493634 0.0285"/>
    <axis xyz="-1 0 0"/>
    <limit effort="1000" lower="0.0" upper="1.0" velocity="6.5"/>
    <dynamics damping="0.7"/>
  </joint>
 
  <!-- rh_p12_rn_r2 -->
  <link name="rh_p12_rn_r2">
    <collision>
      <origin rpy="0 0 0" xyz="0 0 0"/>
      <geometry>
        <mesh filename="meshes/stl/r2.stl" scale="0.001 0.001 0.001"/>
      </geometry>
    </collision>
    <visual>
      <origin rpy="0 0 0" xyz="0 0 0"/>
      <geometry>
        <mesh filename="meshes/stl/r2.stl" scale="0.001 0.001 0.001"/>
      </geometry>
      <material name="black"/>
    </visual>
    <inertial>
      <origin rpy="0 0 0" xyz="0.000 0.006 0.011"/>
      <mass value="0.022"/>
      <!--<inertia ixx="0.0" ixy="0.0" ixz="0.0" iyy="0.00001" iyz="0.0" izz="0.0" />-->
      <inertia ixx="1.0" ixy="0.0" ixz="0.0" iyy="1.0" iyz="0.0" izz="1.0"/>
    </inertial>
  </link>
  <!-- Left Joint 1 -->
  <joint name="rh_l1" type="revolute">
    <parent link="rh_p12_rn_base"/>
    <child link="rh_p12_rn_l1"/>collision
    <origin rpy="0 0 0" xyz="0.0 -0.008 0.048"/>
    <axis xyz="-1 0 0"/>
    <limit effort="1000" lower="0.0" upper="1.1" velocity="6.5"/>
    <mimic joint="rh_p12_rn"/>
    <dynamics damping="0.7"/>

  </joint>
 
  <!-- rh_p12_rn_l1 -->
  <link name="rh_p12_rn_l1">
    <collision>
      <origin rpy="0 0 0" xyz="0 0 0"/>
      <geometry>
        <mesh filename="meshes/stl/l1.stl" scale="0.001 0.001 0.001"/>
      </geometry>
    </collision>
    <visual>
      <origin rpy="0 0 0" xyz="0 0 0"/>
      <geometry>
        <mesh filename="meshes/stl/l1.stl" scale="0.001 0.001 0.001"/>
      </geometry>
      <material name="black"/>
    </visual>
    <inertial>
      <origin rpy="0 0 0" xyz="0.000 -0.034 0.004"/>
      <mass value="0.068"/>
      <!--<inertia ixx="0.00004" ixy="0.0" ixz="0.0" iyy="0.00002" iyz="0.00001" izz="0.00002" />-->
      <inertia ixx="1.0" ixy="0.0" ixz="0.0" iyy="1.0" iyz="0.0" izz="1.0"/>
    </inertial>
  </link>
  <!-- Left Joint 2 -->
  <joint name="rh_l2" type="revolute">
    <parent link="rh_p12_rn_l1"/>
    <child link="rh_p12_rn_l2"/>
    <origin rpy="0 0 0" xyz="0.0 -0.0493634 0.0285"/>
    <axis xyz="1 0 0"/>
    <limit effort="1000" lower="0.0" upper="1.0" velocity="6.5"/>
    <dynamics damping="0.7"/>
    <mimic joint="rh_r2"/>
  </joint>
 
  <!-- rh_p12_rn_l2 -->
  <link name="rh_p12_rn_l2">
    <collision>
      <origin rpy="0 0 0" xyz="0 0 0"/>
      <geometry>
        <mesh filename="meshes/stl/l2.stl" scale="0.001 0.001 0.001"/>
      </geometry>
    </collision>
    <visual>
      <origin rpy="0 0 0" xyz="0 0 0"/>
      <geometry>
        <mesh filename="meshes/stl/l2.stl" scale="0.001 0.001 0.001"/>
      </geometry>
      <material name="black"/>
    </visual>
    <inertial>
      <origin rpy="0 0 0" xyz="0.000 -0.006 0.011"/>
      <mass value="0.022"/>
      <!--<inertia ixx="0.0" ixy="0.0" ixz="0.0" iyy="0.00001" iyz="0.0" izz="0.0" />-->
      <inertia ixx="1.0" ixy="0.0" ixz="0.0" iyy="1.0" iyz="0.0" izz="1.0"/>
    </inertial>
  </link>



</robot>

